Workbook

Sheet 表紙・説明
A1: 実地調査用 テレッサ（訪問介護サービス提供記録）モックデータ
A3: ※重要 | B3: 本ファイルの利用者・ヘルパー・被保険者番号・記録内容はすべて架空のモックデータです。実在の人物・記録とは関係ありません。
A4: 用途 | B4: 実地調査（運営指導）に向けた記録様式の確認、記載レベルの統一、職員研修用
A5: 法人名 | B5: 株式会社dhpケアマネジメント
A6: 事業所名 | B6: いいかいご訪問介護（モック）
A7: 事業所番号 | B7: 27000000XX（モック）
A8: 地域区分・単価 | B8: 大阪市（2級地） 訪問介護 11.12円/単位（2027年4月改定で見直し）
A9: 対象期間 | B9: 2026年10月01日 〜 2026年10月31日
A10: 収録件数 | B10: 利用者 5名 / 記録 71件
A11: シート構成 | B11: ①利用者一覧 ②記録一覧（実績・単位数） ③利用者別月間集計 ④テレッサ（印刷用・1件1ページA4）
A12: 運営指導での主な確認点 | B12: ・計画（訪問介護計画・サービス提供票）と実績の時間/区分の整合 ・提供時間（開始/終了）の実時間記載 ・具体的なサービス内容と利用者の心身状況の記録 ・利用者確認（サイン/押印） ・異変時の報告・連絡の記録（サ責/ケアマネ/家族） ・2時間ルール、20分未満の扱い、生活援助の算定要件
A13: 単位数の根拠 | B13: 2024年度介護報酬改定の訪問介護基本単位（身体1=244、身体2=387、身体3=567、生活2=179、生活3=220、生活援助加算=65/20分）。加算（特定事業所加算・処遇改善加算等）は未計上。

Sheet 利用者一覧
A1: 利用者ID | B1: 氏名（架空） | C1: フリガナ | D1: 性別 | E1: 年齢 | F1: 要介護度 | G1: 被保険者番号 | H1: 担当ケアマネ | I1: 計画（曜日・区分・開始・分） | J1: 特記
A2: U001 | B2: 山田 花子 | C2: ヤマダ ハナコ | D2: 女 | E2: 84 | F2: 要介護2 | G2: 0000000001（モック） | H2: いいかいご居宅介護支援 担当A（モック） | I2: 月 身体1生活1 09:00〜 60分 水 身体2 09:00〜 45分 金 身体1生活1 09:00〜 60分 | J2: 独居。右膝OA。入浴は見守り〜一部介助。
A3: U002 | B3: 佐藤 一郎 | C3: サトウ イチロウ | D3: 男 | E3: 79 | F3: 要介護3 | G3: 0000000002（モック） | H3: いいかいご居宅介護支援 担当B（モック） | I3: 月 身体2 10:30〜 50分 火 身体2 10:30〜 50分 木 身体2 10:30〜 50分 土 身体2 10:30〜 50分 | J3: 脳梗塞後遺症（左片麻痺）。妻と二人暮らし。
A4: U003 | B4: 鈴木 和子 | C4: スズキ カズコ | D4: 女 | E4: 88 | F4: 要介護1 | G4: 0000000003（モック） | H4: いいかいご居宅介護支援 担当A（モック） | I4: 火 生活3 14:00〜 60分 金 生活3 14:00〜 60分 | J4: 独居。軽度認知症。買物・調理援助中心。
A5: U004 | B5: 高橋 進 | C5: タカハシ ススム | D5: 男 | E5: 91 | F5: 要介護4 | G5: 0000000004（モック） | H5: いいかいご居宅介護支援 担当C（モック） | I5: 月 身体1 07:30〜 25分 水 身体1 07:30〜 25分 金 身体1 07:30〜 25分 月 身体1 17:30〜 25分 水 身体1 17:30〜 25分 金 身体1 17:30〜 25分 | J5: ほぼ臥床。長男同居（日中不在）。おむつ交換・体位変換。
A6: U005 | B6: 田中 美代子 | C6: タナカ ミヨコ | D6: 女 | E6: 76 | F6: 要介護1 | G6: 0000000005（モック） | H6: いいかいご居宅介護支援 担当D（モック） | I6: 木 生活2 13:00〜 45分 | J6: 独居。腰椎圧迫骨折後。掃除・洗濯援助。

Sheet 記録一覧
A1: 記録No | B1: 提供日 | C1: 曜 | D1: 利用者ID | E1: 利用者名 | F1: 計画区分 | G1: 開始 | H1: 終了 | I1: 提供分 | J1: 算定区分 | K1: 単位数 | L1: 金額(円) | M1: 身体介護内容 | N1: 生活援助内容 | O1: 担当ヘルパー | P1: 利用者確認
A2: T0001 | B2: 46296 | C2: 木 | D2: U002 | E2: 佐藤 一郎 | F2: 身体2 | G2: 0.4375 | H2: 0.47222222 | I2: 50 | J2: 身体2 | K2: 387 | L2: =ROUNDDOWN(K2*11.12,0) | M2: 排泄介助、更衣介助、移乗介助、服薬確認 | N2: ― | O2: 加藤 健（介護福祉士） | P2: 済
A3: T0002 | B3: 46296 | C3: 木 | D3: U005 | E3: 田中 美代子 | F3: 生活2 | G3: 0.54305556 | H3: 0.57083333 | I3: 40 | J3: 生活2 | K3: 179 | L3: =ROUNDDOWN(K3*11.12,0) | M3: ― | N3: 掃除、ゴミ出し | O3: 中村 真理（介護福祉士） | P3: 済
A4: T0003 | B4: 46297 | C4: 金 | D4: U001 | E4: 山田 花子 | F4: 身体1生活1 | G4: 0.375 | H4: 0.41736111 | I4: 61 | J4: 身体1生活1 | K4: 309 | L4: =ROUNDDOWN(K4*11.12,0) | M4: 入浴介助、自立支援見守り | N4: 掃除 | O4: 小林 恵（初任者研修） | P4: 済
A5: T0004 | B5: 46297 | C5: 金 | D5: U003 | E5: 鈴木 和子 | F5: 生活3 | G5: 0.58541667 | H5: 0.62708333 | I5: 60 | J5: 生活3 | K5: 220 | L5: =ROUNDDOWN(K5*11.12,0) | M5: ― | N5: 掃除、配膳・下膳 | O5: 渡辺 翔（初任者研修） | P5: 済
A6: T0005 | B6: 46297 | C6: 金 | D6: U004 | E6: 高橋 進 | F6: 身体1 | G6: 0.31111111 | H6: 0.33125 | I6: 29 | J6: 身体1 | K6: 244 | L6: =ROUNDDOWN(K6*11.12,0) | M6: おむつ交換、清拭、体位変換、服薬確認 | N6: ― | O6: 中村 真理（介護福祉士） | P6: 済
A7: T0006 | B7: 46297 | C7: 金 | D7: U004 | E7: 高橋 進 | F7: 身体1 | G7: 0.72916667 | H7: 0.74930556 | I7: 29 | J7: 身体1 | K7: 244 | L7: =ROUNDDOWN(K7*11.12,0) | M7: 清拭、体位変換 | N7: ― | O7: 中村 真理（介護福祉士） | P7: 済
A8: T0007 | B8: 46298 | C8: 土 | D8: U002 | E8: 佐藤 一郎 | F8: 身体2 | G8: 0.4375 | H8: 0.47152778 | I8: 49 | J8: 身体2 | K8: 387 | L8: =ROUNDDOWN(K8*11.12,0) | M8: 排泄介助、入浴介助、移乗介助 | N8: ― | O8: 渡辺 翔（初任者研修） | P8: 済
A9: T0008 | B9: 46300 | C9: 月 | D9: U001 | E9: 山田 花子 | F9: 身体1生活1 | G9: 0.37361111 | H9: 0.41527778 | I9: 60 | J9: 身体1生活1 | K9: 309 | L9: =ROUNDDOWN(K9*11.12,0) | M9: 入浴介助、整容、更衣介助、服薬確認、自立支援見守り | N9: 掃除 | O9: 中村 真理（介護福祉士） | P9: 済
A10: T0009 | B10: 46300 | C10: 月 | D10: U002 | E10: 佐藤 一郎 | F10: 身体2 | G10: 0.4375 | H10: 0.47222222 | I10: 50 | J10: 身体2 | K10: 387 | L10: =ROUNDDOWN(K10*11.12,0) | M10: 排泄介助、入浴介助、移乗介助、服薬確認 | N10: ― | O10: 小林 恵（初任者研修） | P10: 済
A11: T0010 | B11: 46300 | C11: 月 | D11: U004 | E11: 高橋 進 | F11: 身体1 | G11: 0.3125 | H11: 0.33055556 | I11: 26 | J11: 身体1 | K11: 244 | L11: =ROUNDDOWN(K11*11.12,0) | M11: おむつ交換、清拭、体位変換、服薬確認 | N11: ― | O11: 伊藤 由美（実務者研修） | P11: 済
A12: T0011 | B12: 46300 | C12: 月 | D12: U004 | E12: 高橋 進 | F12: 身体1 | G12: 0.73125 | H12: 0.74930556 | I12: 26 | J12: 身体1 | K12: 244 | L12: =ROUNDDOWN(K12*11.12,0) | M12: おむつ交換、清拭、体位変換 | N12: ― | O12: 伊藤 由美（実務者研修） | P12: 済
A13: T0012 | B13: 46301 | C13: 火 | D13: U002 | E13: 佐藤 一郎 | F13: 身体2 | G13: 0.4375 | H13: 0.47222222 | I13: 50 | J13: 身体2 | K13: 387 | L13: =ROUNDDOWN(K13*11.12,0) | M13: 入浴介助、更衣介助 | N13: ― | O13: 加藤 健（介護福祉士） | P13: 済
... A72: T0071 | B72: 46326 | C72: 土 | D72: U002 | E72: 佐藤 一郎 | F72: 身体2 | G72: 0.4375 | H72: 0.47152778 | I72: 49 | J72: 身体2 | K72: 387 | L72: =ROUNDDOWN(K72*11.12,0) | M72: 排泄介助、入浴介助、移乗介助 | N72: ― | O72: 加藤 健（介護福祉士） | P72: 済
J73: 合計 | K73: =SUM(K2:K72) | L73: =SUM(L2:L72)

Sheet 利用者別月間集計
A1: 利用者ID | B1: 氏名 | C1: 要介護度 | D1: 回数 | E1: 合計提供分 | F1: 合計単位数 | G1: 金額(円)
A2: U001 | B2: 山田 花子 | C2: 要介護2 | D2: =COUNTIF(記録一覧!$D$2:$D$72,A2) | E2: =SUMIF(記録一覧!$D$2:$D$72,A2,記録一覧!$I$2:$I$72) | F2: =SUMIF(記録一覧!$D$2:$D$72,A2,記録一覧!$K$2:$K$72) | G2: =SUMIF(記録一覧!$D$2:$D$72,A2,記録一覧!$L$2:$L$72)
A3: U002 | B3: 佐藤 一郎 | C3: 要介護3 | D3: =COUNTIF(記録一覧!$D$2:$D$72,A3) | E3: =SUMIF(記録一覧!$D$2:$D$72,A3,記録一覧!$I$2:$I$72) | F3: =SUMIF(記録一覧!$D$2:$D$72,A3,記録一覧!$K$2:$K$72) | G3: =SUMIF(記録一覧!$D$2:$D$72,A3,記録一覧!$L$2:$L$72)
A4: U003 | B4: 鈴木 和子 | C4: 要介護1 | D4: =COUNTIF(記録一覧!$D$2:$D$72,A4) | E4: =SUMIF(記録一覧!$D$2:$D$72,A4,記録一覧!$I$2:$I$72) | F4: =SUMIF(記録一覧!$D$2:$D$72,A4,記録一覧!$K$2:$K$72) | G4: =SUMIF(記録一覧!$D$2:$D$72,A4,記録一覧!$L$2:$L$72)
A5: U004 | B5: 高橋 進 | C5: 要介護4 | D5: =COUNTIF(記録一覧!$D$2:$D$72,A5) | E5: =SUMIF(記録一覧!$D$2:$D$72,A5,記録一覧!$I$2:$I$72) | F5: =SUMIF(記録一覧!$D$2:$D$72,A5,記録一覧!$K$2:$K$72) | G5: =SUMIF(記録一覧!$D$2:$D$72,A5,記録一覧!$L$2:$L$72)
A6: U005 | B6: 田中 美代子 | C6: 要介護1 | D6: =COUNTIF(記録一覧!$D$2:$D$72,A6) | E6: =SUMIF(記録一覧!$D$2:$D$72,A6,記録一覧!$I$2:$I$72) | F6: =SUMIF(記録一覧!$D$2:$D$72,A6,記録一覧!$K$2:$K$72) | G6: =SUMIF(記録一覧!$D$2:$D$72,A6,記録一覧!$L$2:$L$72)
C7: 合計 | D7: =SUM(D2:D6) | E7: =SUM(E2:E6) | F7: =SUM(F2:F6) | G7: =SUM(G2:G6)
A9: ※記録一覧の金額は1回ごとの参考値。利用者別の合計はサービス提供票の別表と同じく合計単位×11.12円（端数切捨て）で計算すること。加算・利用者負担割合は未計上。

Sheet テレッサ（印刷用）
A1: 訪問介護サービス提供記録（テレッサ） | G1: No. T0001
A2: 株式会社dhpケアマネジメント いいかいご訪問介護（モック） 事業所番号 27000000XX（モック）
A3: ※架空のモックデータ（実地調査準備・研修用）
A4: 利用者名 | B4: 佐藤 一郎 様 | D4: 要介護度 | E4: 要介護3 | F4: 被保険者番号 | G4: 0000000002（モック）
A5: 提供日 | B5: 2026年10月01日（木） | D5: 提供時間 | E5: 10:30 〜 11:20（50分） | G5: 算定区分 | H5: 身体2
A6: 計画区分 | B6: 身体2 | D6: 単位数 | E6: 387単位 | F6: 派遣人数 | G6: 1名
A7: 体温 | B7: 36.3℃ | C7: 血圧 | D7: 128/82 | E7: 脈拍 | F7: 67回/分 | G7: 顔色・様子 | H7: 良好
A8: 食事摂取 | B8: ― | E8: 排泄 | F8: 尿○ 便×
A9: ■ 身体介護
A10: ☑ 排泄介助 | C10: □ おむつ交換 | E10: □ 食事介助 | G10: □ 入浴介助
A11: □ 部分浴（足浴） | C11: □ 清拭 | E11: □ 整容 | G11: ☑ 更衣介助
A12: □ 体位変換 | C12: ☑ 移乗介助 | E12: □ 移動介助 | G12: ☑ 服薬確認
A13: □ 起床介助 | C13: □ 就寝介助 | E13: □ 自立支援見守り
A14: ■ 生活援助
A15: □ 掃除 | C15: □ 洗濯 | E15: □ 調理 | G15: □ 配膳・下膳
A16: □ 買物 | C16: □ ベッドメイク | E16: □ 衣類整理 | G16: □ ゴミ出し
A17: ■ 利用者の状態・サービス提供時の特記事項
A18: ベッドから車椅子へ移乗介助。左側に注意。トイレにて排泄介助、排尿あり・排便なし。
A24: 報告・連絡 | B24: なし
A25: 退室時確認 | B25: ☑ 火の元 ☑ 戸締り ☑ 電気・水道 ☑ 貴重品の所在 ☑ 次回訪問日の伝達
A26: 担当ヘルパー | B26: 加藤 健（介護福祉士） | E26: サ責確認 | F26: 中村 真理 確認済
A27: 利用者確認 | B27: 佐藤 一郎（署名欄・モック） | E27: 確認日時 | F27: 2026/10/01 11:20
A29: 訪問介護サービス提供記録（テレッサ） | G29: No. T0002
A30: 株式会社dhpケアマネジメント いいかいご訪問介護（モック） 事業所番号 27000000XX（モック）
A31: ※架空のモックデータ（実地調査準備・研修用）
A32: 利用者名 | B32: 田中 美代子 様 | D32: 要介護度 | E32: 要介護1 | F32: 被保険者番号 | G32: 0000000005（モック）
A33: 提供日 | B33: 2026年10月01日（木） | D33: 提供時間 | E33: 13:02 〜 13:42（40分） | G33: 算定区分 | H33: 生活2
A34: 計画区分 | B34: 生活2 | D34: 単位数 | E34: 179単位 | F34: 派遣人数 | G34: 1名
A35: 体温 | B35: 36.4℃ | C35: 血圧 | D35: 122/68 | E35: 脈拍 | F35: 73回/分 | G35: 顔色・様子 | H35: 良好
A36: 食事摂取 | B36: ― | E36: 排泄 | F36: ―
A37: ■ 身体介護
A38: □ 排泄介助 | C38: □ おむつ交換 | E38: □ 食事介助 | G38: □ 入浴介助
A39: □ 部分浴（足浴） | C39: □ 清拭 | E39: □ 整容 | G39: □ 更衣介助
A40: □ 体位変換 | C40: □ 移乗介助 | E40: □ 移動介助 | G40: □ 服薬確認
A41: □ 起床介助 | C41: □ 就寝介助 | E41: □ 自立支援見守り
A42: ■ 生活援助
A43: ☑ 掃除 | C43: □ 洗濯 | E43: □ 調理 | G43: □ 配膳・下膳
A44: □ 買物 | C44: □ ベッドメイク | E44: □ 衣類整理 | G44: ☑ ゴミ出し
A45: ■ 利用者の状態・サービス提供時の特記事項
A46: 掃除機がけ・拭き掃除。歩行は杖使用で安定。表情明るい。
...
